<?xml version="1.0"?>
<!-- Open_Manipulator Chain -->
<robot xmlns:xacro="http://ros.org/wiki/xacro">

  <link
    name="base_link">
    <inertial>
      <origin
        xyz="0.00074502 6.0999E-06 0.0023718"
        rpy="0 0 0" />
      <mass
        value="4.2883" />
      <inertia
        ixx="0.010171"
        ixy="2.9086E-05"
        ixz="-0.0010273"
        iyy="0.016694"
        iyz="3.9761E-05"
        izz="0.015295" />
    </inertial>
    <visual>
      <origin
        xyz="0 0 0"
        rpy="0 0 0" />
      <geometry>
        <mesh
          filename="package://open_manipulator_description/meshes/base_link.STL" />
      </geometry>
      <material
        name="grey"/>
    </visual>
    <collision>
      <origin
        xyz="0 0 0"
        rpy="0 0 0" />
      <geometry>
        <mesh
          filename="package://open_manipulator_description/meshes/base_link.STL" />
      </geometry>
    </collision>
  </link>
  <link
    name="propeller_link1">
    <inertial>
      <origin
        xyz="-1.3853E-09 -1.286E-11 0.0076077"
        rpy="0 0 0" />
      <mass
        value="0.01068" />
      <inertia
        ixx="8.941E-07"
        ixy="-8.1765E-08"
        ixz="2.7924E-14"
        iyy="8.2131E-05"
        iyz="7.4368E-15"
        izz="8.2751E-05" />
    </inertial>
    <visual>
      <origin
        xyz="0 0 0"
        rpy="0 0 0" />
      <geometry>
        <mesh
          filename="package://open_manipulator_description/meshes/propeller_link1.STL" />
      </geometry>
      <material
        name="grey"/>
    </visual>
    <collision>
      <origin
        xyz="0 0 0"
        rpy="0 0 0" />
      <geometry>
        <mesh
          filename="package://open_manipulator_description/meshes/propeller_link1.STL" />
      </geometry>
    </collision>
  </link>
  <joint
    name="propeller_joint1"
    type="continuous">
    <origin
      xyz="0.20575 0.2577 0.089"
      rpy="0 0 0" />
    <parent
      link="base_link" />
    <child
      link="propeller_link1" />
    <axis
      xyz="0 0 1" />
    <limit
      effort="100"
      velocity="100" />
  </joint>
  <link
    name="propeller_link2">
    <inertial>
      <origin
        xyz="0.00910880132669048 -5.32711789675289E-05 0.00759679233335697"
        rpy="0 0 0" />
      <mass
        value="0.0122360049560338" />
      <inertia
        ixx="9.93278673552758E-07"
        ixy="2.69537991117596E-08"
        ixz="3.62570565543768E-07"
        iyy="3.84909547564719E-05"
        iyz="-4.0529018109384E-08"
        izz="3.92080160609976E-05" />
    </inertial>
    <visual>
      <origin
        xyz="0 0 0"
        rpy="0 0 0" />
      <geometry>
        <mesh
          filename="package://open_manipulator_description/meshes/propeller_link2.STL" />
      </geometry>
      <material
        name="grey"/>
    </visual>
    <collision>
      <origin
        xyz="0 0 0"
        rpy="0 0 0" />
      <geometry>
        <mesh
          filename="package://open_manipulator_description/meshes/propeller_link2.STL" />
      </geometry>
    </collision>
  </link>
  <joint
    name="propeller_joint2"
    type="continuous">
    <origin
      xyz="0.20575 -0.2577 0.089"
      rpy="0 0 0" />
    <parent
      link="base_link" />
    <child
      link="propeller_link2" />
    <axis
      xyz="0 0 1" />
    <limit
      effort="100"
      velocity="100" />
  </joint>
  <link
    name="propeller_link3">
    <inertial>
      <origin
        xyz="-1.38529199222859E-09 -1.2860018605565E-11 0.00760765733681423"
        rpy="0 0 0" />
      <mass
        value="0.0106802619311423" />
      <inertia
        ixx="8.94096643340685E-07"
        ixy="-8.17648442204221E-08"
        ixz="2.79240019025484E-14"
        iyy="8.21313960888616E-05"
        iyz="7.43677081936356E-15"
        izz="8.27513886291376E-05" />
    </inertial>
    <visual>
      <origin
        xyz="0 0 0"
        rpy="0 0 0" />
      <geometry>
        <mesh
          filename="package://open_manipulator_description/meshes/propeller_link3.STL" />
      </geometry>
      <material
        name="grey"/>
    </visual>
    <collision>
      <origin
        xyz="0 0 0"
        rpy="0 0 0" />
      <geometry>
        <mesh
          filename="package://open_manipulator_description/meshes/propeller_link3.STL" />
      </geometry>
    </collision>
  </link>
  <joint
    name="propeller_joint3"
    type="continuous">
    <origin
      xyz="-0.22584 -0.23976 0.089"
      rpy="0 0 0" />
    <parent
      link="base_link" />
    <child
      link="propeller_link3" />
    <axis
      xyz="0 0 1" />
    <limit
      effort="100"
      velocity="100" />
  </joint>
  <link
    name="propeller_link4">
    <inertial>
      <origin
        xyz="0.00910880132669595 -5.32499604787851E-05 0.0075967860312664"
        rpy="0 0 0" />
      <mass
        value="0.0122360049560337" />
      <inertia
        ixx="9.93278675305645E-07"
        ixy="2.65513314130224E-08"
        ixz="3.62683363519345E-07"
        iyy="3.84909548123461E-05"
        iyz="-4.05289320878409E-08"
        izz="3.92080160068796E-05" />
    </inertial>
    <visual>
      <origin
        xyz="0 0 0"
        rpy="0 0 0" />
      <geometry>
        <mesh
          filename="package://open_manipulator_description/meshes/propeller_link4.STL" />
      </geometry>
      <material
        name="grey"/>
    </visual>
    <collision>
      <origin
        xyz="0 0 0"
        rpy="0 0 0" />
      <geometry>
        <mesh
          filename="package://open_manipulator_description/meshes/propeller_link4.STL" />
      </geometry>
    </collision>
  </link>
  <joint
    name="propeller_joint4"
    type="continuous">
    <origin
      xyz="-0.22584 0.23976 0.089"
      rpy="0 0 0" />
    <parent
      link="base_link" />
    <child
      link="propeller_link4" />
    <axis
      xyz="0 0 1" />
    <limit
      effort="100"
      velocity="100" />
  </joint>
  <link
    name="link1">
    <inertial>
      <origin
        xyz="0.00028546 5.3895E-16 -0.017935"
        rpy="0 0 0" />
      <mass
        value="0.042691" />
      <inertia
        ixx="6.8032E-06"
        ixy="2.2501E-19"
        ixz="1.0875E-07"
        iyy="1.1936E-05"
        iyz="-2.254E-20"
        izz="1.055E-05" />
    </inertial>
    <visual>
      <origin
        xyz="0 0 0"
        rpy="0 0 0" />
      <geometry>
        <mesh
          filename="package://open_manipulator_description/meshes/link1.STL" />
      </geometry>
      <material
        name="grey"/>
    </visual>
    <collision>
      <origin
        xyz="0 0 0"
        rpy="0 0 0" />
      <geometry>
        <mesh
          filename="package://open_manipulator_description/meshes/link1.STL" />
      </geometry>
    </collision>
  </link>
  <joint
    name="joint0"
    type="fixed">
    <origin
      xyz="0.114 0 -0.054006"
      rpy="0 0 0" />
    <parent
      link="base_link" />
    <child
      link="link1" />
    <axis
      xyz="0 0 0" />
  </joint>
  <link
    name="link2">
    <inertial>
      <origin
        xyz="-8.6881E-11 0.00061101 -0.046806"
        rpy="0 0 0" />
      <mass
        value="0.045068" />
      <inertia
        ixx="1.2486E-05"
        ixy="-5.5947E-14"
        ixz="-4.333E-14"
        iyy="1.0631E-05"
        iyz="-1.9925E-08"
        izz="7.4738E-06" />
    </inertial>
    <visual>
      <origin
        xyz="0 0 0"
        rpy="0 0 0" />
      <geometry>
        <mesh
          filename="package://open_manipulator_description/meshes/link2.STL" />
      </geometry>
      <material
        name="grey"/>
    </visual>
    <collision>
      <origin
        xyz="0 0 0"
        rpy="0 0 0" />
      <geometry>
        <mesh
          filename="package://open_manipulator_description/meshes/link2.STL" />
      </geometry>
    </collision>
  </link>
  <joint
    name="joint1"
    type="revolute">
    <origin
      xyz="0.012 0 -0.017"
      rpy="0 0 0" />
    <parent
      link="link1" />
    <child
      link="link2" />
    <axis
      xyz="0 0 -1" />
    <limit
      lower="-1.5"
      upper="1.5"
      effort="1"
      velocity="4.8" />
  </joint>
  <link
    name="link3">
    <inertial>
      <origin
        xyz="0.0086487 0.00041283 -0.1056"
        rpy="0 0 0" />
      <mass
        value="0.066626" />
      <inertia
        ixx="1.9817E-05"
        ixy="1.9884E-08"
        ixz="1.1649E-10"
        iyy="2.1817E-05"
        iyz="-8.2506E-10"
        izz="1.6434E-05" />
    </inertial>
    <visual>
      <origin
        xyz="0 0 0"
        rpy="0 0 0" />
      <geometry>
        <mesh
          filename="package://open_manipulator_description/meshes/link3.STL" />
      </geometry>
      <material
        name="grey"/>
    </visual>
    <collision>
      <origin
        xyz="0 0 0"
        rpy="0 0 0" />
      <geometry>
        <mesh
          filename="package://open_manipulator_description/meshes/link3.STL" />
      </geometry>
    </collision>
  </link>
  <joint
    name="joint2"
    type="revolute">
    <origin
      xyz="0 0 -0.0595"
      rpy="0 0 0" />
    <parent
      link="link2" />
    <child
      link="link3" />
    <axis
      xyz="0 1 0" />
    <limit
      lower="-1.65"
      upper="1.57"
      effort="1"
      velocity="4.8" />
  </joint>
  <link
    name="link4">
    <inertial>
      <origin
        xyz="0.094148 0.00045083 -8.8171E-07"
        rpy="0 0 0" />
      <mass
        value="0.061077" />
      <inertia
        ixx="1.0216E-05"
        ixy="1.9877E-08"
        ixz="2.6581E-11"
        iyy="1.5131E-05"
        iyz="-4.7919E-11"
        izz="1.8336E-05" />
    </inertial>
    <visual>
      <origin
        xyz="0 0 0"
        rpy="0 0 0" />
      <geometry>
        <mesh
          filename="package://open_manipulator_description/meshes/link4.STL" />
      </geometry>
      <material
        name="grey"/>
    </visual>
    <collision>
      <origin
        xyz="0 0 0"
        rpy="0 0 0" />
      <geometry>
        <mesh
          filename="package://open_manipulator_description/meshes/link4.STL" />
      </geometry>
    </collision>
  </link>
  <joint
    name="joint3"
    type="revolute">
    <origin
      xyz="0.024 0 -0.128"
      rpy="0 0 0" />
    <parent
      link="link3" />
    <child
      link="link4" />
    <axis
      xyz="0 1 0" />
    <limit
      lower="-1.5"
      upper="1.5"
      effort="1"
      velocity="4.8" />
  </joint>
  <link
    name="link5">
    <inertial>
      <origin
        xyz="0.049623 -2.9307E-08 0.0083646"
        rpy="0 0 0" />
      <mass
        value="0.080366" />
      <inertia
        ixx="3.0765E-05"
        ixy="-4.1606E-09"
        ixz="6.3268E-07"
        iyy="2.4283E-05"
        iyz="6.782E-08"
        izz="2.0111E-05" />
    </inertial>
    <visual>
      <origin
        xyz="0 0 0"
        rpy="0 0 0" />
      <geometry>
        <mesh
          filename="package://open_manipulator_description/meshes/link5.STL" />
      </geometry>
      <material
        name="grey"/>
    </visual>
    <collision>
      <origin
        xyz="0 0 0"
        rpy="0 0 0" />
      <geometry>
        <mesh
          filename="package://open_manipulator_description/meshes/link5.STL" />
      </geometry>
    </collision>
  </link>
  <joint
    name="joint4"
    type="revolute">
    <origin
      xyz="0.124 0 0"
      rpy="0 0 0" />
    <parent
      link="link4" />
    <child
      link="link5" />
    <axis
      xyz="0 1 0" />
    <limit
      lower="-1.7"
      upper="2.042"
      effort="1"
      velocity="4.8" />
  </joint>
  <link
    name="gripper_link">
    <inertial>
      <origin
        xyz="0.0076219 0.0047109 -7.1673E-07"
        rpy="0 0 0" />
      <mass
        value="0.024997" />
      <inertia
        ixx="7.0228E-06"
        ixy="2.0587E-07"
        ixz="-4.6329E-10"
        iyy="1.2476E-05"
        iyz="-2.2699E-10"
        izz="7.7793E-06" />
    </inertial>
    <visual>
      <origin
        xyz="0 0 0"
        rpy="0 0 0" />
      <geometry>
        <mesh
          filename="package://open_manipulator_description/meshes/gripper_link.STL" />
      </geometry>
      <material
        name="grey"/>
    </visual>
    <collision>
      <origin
        xyz="0 0 0"
        rpy="0 0 0" />
      <geometry>
        <mesh
          filename="package://open_manipulator_description/meshes/gripper_link.STL" />
      </geometry>
    </collision>
  </link>
  <joint
    name="gripper"
    type="prismatic">
    <origin
      xyz="0.0816 0.030798 -0.00035"
      rpy="0 0 0" />
    <parent
      link="link5" />
    <child
      link="gripper_link" />
    <axis
      xyz="0 1 0" />
    <limit
      lower="-0.01"
      upper="0.019"
      effort="0"
      velocity="0" />
  </joint>
  <link
    name="gripper_link_sub">
    <inertial>
      <origin
        xyz="0.0076219 -0.0047109 7.1673E-07"
        rpy="0 0 0" />
      <mass
        value="0.024997" />
      <inertia
        ixx="7.0228E-06"
        ixy="-2.0587E-07"
        ixz="4.6329E-10"
        iyy="1.2476E-05"
        iyz="-2.2699E-10"
        izz="7.7793E-06" />
    </inertial>
    <visual>
      <origin
        xyz="0 0 0"
        rpy="0 0 0" />
      <geometry>
        <mesh
          filename="package://open_manipulator_description/meshes/gripper_link_sub.STL" />
      </geometry>
      <material
        name="grey"/>
    </visual>
    <collision>
      <origin
        xyz="0 0 0"
        rpy="0 0 0" />
      <geometry>
        <mesh
          filename="package://open_manipulator_description/meshes/gripper_link_sub.STL" />
      </geometry>
    </collision>
  </link>
  <joint
    name="gripper_sub"
    type="prismatic">
    <origin
      xyz="0.0816 -0.030798 -0.00035"
      rpy="0 0 0" />
    <parent
      link="link5" />
    <child
      link="gripper_link_sub" />
    <axis
      xyz="0 -1 0" />
    <limit
      lower="-0.01"
      upper="0.019"
      effort="1"
      velocity="4.8" />
    <mimic
      joint="gripper"
      multiplier="1"
      offset="0" />
  </joint>
  <link
    name="end_effector_link">
    <inertial>
      <origin
        xyz="0 0 0"
        rpy="0 0 0" />
      <mass
        value="0.001" />
      <inertia
        ixx="1.6667E-08"
        ixy="-2.1684E-25"
        ixz="-8.4057E-25"
        iyy="1.6667E-08"
        iyz="0"
        izz="1.6667E-08" />
    </inertial>
    <visual>
      <origin
        xyz="0 0 0"
        rpy="0 0 0" />
      <geometry>
        <mesh
          filename="package://open_manipulator_description/meshes/end_effector_link.STL" />
      </geometry>
      <material
        name="green"/>
    </visual>
    <collision>
      <origin
        xyz="0 0 0"
        rpy="0 0 0" />
      <geometry>
        <mesh
          filename="package://open_manipulator_description/meshes/end_effector_link.STL" />
      </geometry>
    </collision>
  </link>
  <joint
    name="end_effector_joint"
    type="fixed">
    <origin
      xyz="0.11758 4.4858E-05 -8.8638E-05"
      rpy="0 0 0" />
    <parent
      link="link5" />
    <child
      link="end_effector_link" />
    <axis
      xyz="0 0 0" />
  </joint>
  <link
    name="cam_link">
    <inertial>
      <origin
        xyz="0.00093101 -7.6907E-18 -0.00059615"
        rpy="0 0 0" />
      <mass
        value="0.0024355" />
      <inertia
        ixx="2.9768E-07"
        ixy="-4.821E-22"
        ixz="-5.6631E-09"
        iyy="1.6811E-07"
        iyz="3.509E-23"
        izz="1.5494E-07" />
    </inertial>
    <visual>
      <origin
        xyz="0 0 0"
        rpy="0 0 0" />
      <geometry>
        <mesh
          filename="package://open_manipulator_description/meshes/cam_link.STL" />
      </geometry>
      <material
        name="grey"/>
    </visual>
    <collision>
      <origin
        xyz="0 0 0"
        rpy="0 0 0" />
      <geometry>
        <mesh
          filename="package://open_manipulator_description/meshes/cam_link.STL" />
      </geometry>
    </collision>
  </link>
  <joint
    name="cam_joint"
    type="fixed">
    <origin
      xyz="0.0445 0 0.0568"
      rpy="0 0 0" />
    <parent
      link="link5" />
    <child
      link="cam_link" />
    <axis
      xyz="0 0 0" />
  </joint>
</robot>
